<robot name="pololu">
  <!-- Base link -->
  <link name="base_link">
    <visual>
      <origin xyz="0 0 0.009" rpy="0 0 0" />
      <geometry>
          <cylinder length="0.038" radius="0.045"/>
      </geometry>
      <material name="blue">
        <color rgba="0.3 0.1 .6 1"/>
      </material>
    </visual>
  </link>
  <!-- Sonar Sensor -->
  <link name="sonar_sensor">
    <visual>
      <origin xyz="0 0 0" rpy="0 1.57 0" />
      <geometry>
          <cylinder length="0.015" radius="0.0075"/>
      </geometry>
      <material name="red">
        <color rgba="0.8 0 0 1"/>
      </material>
    </visual>
  </link>
  <joint name="joint_sonar_sensor" type="fixed">
    <parent link="base_link"/>
    <child link="sonar_sensor"/>
    <origin xyz="0.03 0 0.035" rpy="0 0 0" /> 
    <axis xyz="1 0 0" rpy="0 0 0" />
  </joint> 
  <!-- Edison -->
  <link name="edison">
    <visual>
      <origin xyz="0 0 0" rpy="0 0 0" />
      <geometry>
          <box size="0.025 0.055 0.015"/>
      </geometry>
      <material name="green">
        <color rgba="0 0.4 0.2 1"/>
      </material>
    </visual>
  </link>
  <joint name="joint_edison" type="fixed">
    <parent link="base_link"/>
    <child link="edison"/>
    <origin xyz="-0.02 0 0.037" rpy="0 0 0" /> 
    <axis xyz="0 1 0" rpy="0 0 0" />
  </joint> 
  <!-- Front Right Wheel -->
  <link name="f_r_wheel">
    <visual>
      <origin xyz="0 0 0" rpy="1.570795 0 0" />
      <geometry>
          <cylinder length="0.008" radius="0.025" />
      </geometry>
      <material name="black">
        <color rgba="0.05 0.05 0.05 1"/>
      </material>
    </visual>
  </link>
  <joint name="joint_f_r_wheel" type="continuous">
    <parent link="base_link"/>
    <child link="f_r_wheel"/>
    <origin xyz="0 -0.048 0" rpy="0 0 0" /> 
    <axis xyz="0 1 0" rpy="0 0 0" />
  </joint>  
 
  <!-- Front Left Wheel -->
  <link name="f_l_wheel">
    <visual>
      <origin xyz="0 0 0" rpy="1.570795 0 0" />
      <geometry>
          <cylinder length="0.008" radius="0.025" />
      </geometry>
      <material name="black"/>
    </visual>
  </link>
  <joint name="joint_f_l_wheel" type="continuous">
    <parent link="base_link"/>
    <child link="f_l_wheel"/>
    <origin xyz="0 0.048 0" rpy="0 0 0" /> 
    <axis xyz="0 1 0" rpy="0 0 0" />
  </joint>
  
</robot>